Workbook

Sheet Sheet1
A1: NO | B1: NIP | C1: NAMA | D1: PROGRAM STUDI | E1: JAD TERAKHIR | F1: PLOTTING KEILMUAN (2025) | G1: FAKULTAS
A2: 1 | B2: 23990046-3 | C2: AAZ MUHAMMAD HAFIDZ AZIS | D2: S1 REKAYASA PERANGKAT LUNAK (FIF) | E2: ASISTEN AHLI | F2: Artificial Intelligence | G2: FIF
A3: 2 | B3: 24900005-3 | C3: ABDULLAH HANIFAN | D3: S1 PJJ INFORMATIKA (FIF) | E3: NJAD | F3: Computer Security | G3: FIF
A4: 3 | B4: 24960014-3 | C4: ABDULLAH ISKANDAR | D4: S1 INFORMATIKA (FIF) | E4: NJAD | F4: Human Computer Interaction | G4: FIF
A5: 4 | B5: 23780001-3 | C5: ACHMAD LUKMAN | D5: S1 TEKNOLOGI INFORMASI (FIF) | E5: LEKTOR | F5: Artificial Intelligence | G5: FIF
A6: 5 | B6: 06840042-1 | C6: ADE ROMADHONY | D6: S2 INFORMATIKA (FIF) | E6: LEKTOR | F6: Natural Language Processing | G6: FIF
A7: 6 | B7: 21950003-3 | C7: ADITYA FIRMAN IHSAN | D7: S1 INFORMATIKA (FIF) | E7: LEKTOR | F7: Data Modeling and Simulation | G7: FIF
A8: 7 | B8: 00740046-1 | C8: ADIWIJAYA | D8: S3 INFORMATIKA (FIF) | E8: GURU BESAR | F8: Matematika | G8: FIF
A9: 8 | B9: 06810035-1 | C9: AGUNG TOTO WIBOWO | D9: S3 INFORMATIKA (FIF) | E9: LEKTOR | F9: Personalized Recommender System | G9: FIF
A10: 9 | B10: 15850084-1 | C10: AJI GAUTAMA PUTRADA | D10: S1 INFORMATIKA (FIF) | E10: LEKTOR | F10: Information Technology | G10: FIF
A11: 10 | B11: 14890028-1 | C11: ANDITYA ARIFIANTO | D11: S1 INFORMATIKA (FIF) | E11: ASISTEN AHLI | F11: Machine Learning | G11: FIF
A12: 11 | B12: 02760051-1 | C12: ANDRIAN RAKHMATSYAH | D12: S1 INFORMATIKA (FIF) | E12: LEKTOR | F12: Computer Hardware | G12: FIF
A13: 12 | B13: 25980006-3 | C13: ANDY MAULANA YUSUF | D13: S1 INFORMATIKA (FIF) | E13: NJAD | F13: Recommender System | G13: FIF
... A162: 161 | B162: 99750047-1 | C162: Z. K. ABDURAHMAN BAIZAL | D162: S1 INFORMATIKA (FIF) | E162: LEKTOR KEPALA | F162: Recommender System | G162: FIF

Sheet ALL
A1: No | B1: NAMA PEGAWAI TANPA GELAR | C1: KODE | D1: PROGRAM STUDI | E1: Kelompok Keahlian Baru | F1: JFA | G1: Keilmuan | H1: Ajuan JAD
A2: 1 | B2: ADE ROMADHONY | C2: ADE | D2: S2 Informatika | E2: Data Science and Intelligent Systems(DSIS) | F2: Lektor | G2: =VLOOKUP(B2,Sheet1!$C$2:$F$162,4,0) -> Natural Language Processing | H2: Computational Linguistic
A3: 2 | B3: AAZ MUHAMMAD HAFIDZ AZIS | C3: ZHH | D3: S1 Rekayasa Perangkat Lunak | E3: Software Engineering and Algoritm (SEAL) | F3: Asisten Ahli | G3: =VLOOKUP(B3,Sheet1!$C$2:$F$162,4,0) -> Artificial Intelligence
A4: 3 | B4: ABDULLAH HANIFAN | C4: ALH | D4: S1 PJJ Informatika | E4: Communication and Information Technology Insfrastucture (CITI) | F4: NJAD | G4: =VLOOKUP(B4,Sheet1!$C$2:$F$162,4,0) -> Computer Security
A5: 4 | B5: ABDULLAH ISKANDAR | C5: ABK | D5: S1 Informatika | E5: Data Science and Intelligent Systems(DSIS) | F5: NJAD | G5: =VLOOKUP(B5,Sheet1!$C$2:$F$162,4,0) -> Human Computer Interaction
A6: 5 | B6: ACHMAD LUKMAN | C6: ACK | D6: S1 Teknologi Informasi | E6: Data Science and Intelligent Systems(DSIS) | F6: Lektor | G6: =VLOOKUP(B6,Sheet1!$C$2:$F$162,4,0) -> Artificial Intelligence
A7: 6 | B7: ADITYA FIRMAN IHSAN | C7: FMH | D7: S1 Informatika | E7: Data Science and Intelligent Systems(DSIS) | F7: Lektor | G7: =VLOOKUP(B7,Sheet1!$C$2:$F$162,4,0) -> Data Modeling and Simulation
A8: 7 | B8: ADIWIJAYA | C8: ADW | D8: S3 Informatika | E8: Data Science and Intelligent Systems(DSIS) | F8: Guru Besar | G8: =VLOOKUP(B8,Sheet1!$C$2:$F$162,4,0) -> Matematika
A9: 8 | B9: AGUNG TOTO WIBOWO | C9: ATW | D9: S3 Informatika | E9: Data Science and Intelligent Systems(DSIS) | F9: Lektor | G9: =VLOOKUP(B9,Sheet1!$C$2:$F$162,4,0) -> Personalized Recommender System | H9: Recommender System
A10: 9 | B10: AJI GAUTAMA PUTRADA | C10: AJG | D10: S1 Teknologi Informasi | E10: Communication and Information Technology Insfrastucture (CITI) | F10: Lektor | G10: =VLOOKUP(B10,Sheet1!$C$2:$F$162,4,0) -> Information Technology
A11: 10 | B11: ANDY MAULANA YUSUF | C11: ANM | D11: S1 Informatika | E11: Data Science and Intelligent Systems(DSIS) | F11: NJAD | G11: =VLOOKUP(B11,Sheet1!$C$2:$F$162,4,0) -> Recommender System
A12: 11 | B12: ANDITYA ARIFIANTO | C12: ADF | D12: S1 Informatika | E12: Data Science and Intelligent Systems(DSIS) | F12: Asisten Ahli | G12: =VLOOKUP(B12,Sheet1!$C$2:$F$162,4,0) -> Machine Learning
A13: 12 | B13: ANDRIAN RAKHMATSYAH | C13: ADR | D13: S1 Informatika | E13: Communication and Information Technology Insfrastucture (CITI) | F13: Lektor | G13: =VLOOKUP(B13,Sheet1!$C$2:$F$162,4,0) -> Computer Hardware
A14: 13 | B14: ANGELINA PRIMA KURNIATI | C14: APK | D14: S1 Informatika | E14: Data Science and Intelligent Systems(DSIS) | F14: Lektor Kepala | G14: =VLOOKUP(B14,Sheet1!$C$2:$F$162,4,0) -> Process Mining
A15: 14 | B15: ANIQ ATIQI ROHMAWATI | C15: NIQ | D15: S1 Informatika | E15: Data Science and Intelligent Systems(DSIS) | F15: Lektor | G15: =VLOOKUP(B15,Sheet1!$C$2:$F$162,4,0) -> Data Modeling and Simulation
A16: 15 | B16: ANISA HERDIANI | C16: NDN | D16: S1 PJJ Informatika | E16: Software Engineering and Algoritm (SEAL) | F16: Asisten Ahli | G16: =VLOOKUP(B16,Sheet1!$C$2:$F$162,4,0) -> Online Learning Environment
A17: 16 | B17: ANNISA ADITSANIA | C17: TSA | D17: S1 Informatika | E17: Data Science and Intelligent Systems(DSIS) | F17: Asisten Ahli | G17: =VLOOKUP(B17,Sheet1!$C$2:$F$162,4,0) -> Data Modeling and Simulation
A18: 17 | B18: ANUNG ASMORO | C18: NMR | D18: S1 Teknologi Informasi | E18: Software Engineering and Algoritm (SEAL) | F18: NJAD | G18: =VLOOKUP(B18,Sheet1!$C$2:$F$162,4,0) -> Software Engineering
A19: 18 | B19: ARFIVE GANDHI | C19: FVE | D19: S1 Rekayasa Perangkat Lunak | E19: Software Engineering and Algoritm (SEAL) | F19: Lektor | G19: =VLOOKUP(B19,Sheet1!$C$2:$F$162,4,0) -> Software Engineering
A20: 19 | B20: ARI MOESRIAMI BARMAWI | C20: ABW | D20: S2 Ilmu Forensik | E20: Communication and Information Technology Insfrastucture (CITI) | F20: Guru Besar | G20: =VLOOKUP(B20,Sheet1!$C$2:$F$162,4,0) -> Computer Security
A21: 20 | B21: ARIE ARDIYANTI SURYANI | C21: RIE | D21: S2 Informatika | E21: Data Science and Intelligent Systems(DSIS) | F21: Lektor | G21: =VLOOKUP(B21,Sheet1!$C$2:$F$162,4,0) -> Natural Language Processing
... A85: 84 | B85: JONDRI | C85: JDN | D85: S1 Sains Data | E85: Data Science and Intelligent Systems(DSIS) | F85: Lektor Kepala | G85: =VLOOKUP(B85,Sheet1!$C$2:$F$162,4,0) -> Machine Learning
A86: 85 | B86: KEMAS MUSLIM LHAKSMANA | C86: KMM | D86: S1 Informatika | E86: Data Science and Intelligent Systems(DSIS) | F86: Lektor | G86: =VLOOKUP(B86,Sheet1!$C$2:$F$162,4,0) -> Text Mining & Processing | H86: Artificial Intelligence
A87: 86 | B87: KEMAS RAHMAT SALEH WIHARJA | C87: KMS | D87: S1 Sains Data | E87: Data Science and Intelligent Systems(DSIS) | F87: Lektor Kepala | G87: =VLOOKUP(B87,Sheet1!$C$2:$F$162,4,0) -> Knowledge Based System
A88: 87 | B88: KURNIAWAN NUR RAMADHANI | C88: KNR | D88: S1 Informatika | E88: Data Science and Intelligent Systems(DSIS) | F88: Lektor | G88: =VLOOKUP(B88,Sheet1!$C$2:$F$162,4,0) -> Computer Vision
A89: 88 | B89: KUSUMA ADI ACHMAD | C89: KSA | D89: S1 Teknologi Informasi | E89: Communication and Information Technology Insfrastucture (CITI) | F89: Lektor | G89: =VLOOKUP(B89,Sheet1!$C$2:$F$162,4,0) -> Information Technology
A90: 89 | B90: KUSUMA AYU LAKSITOWENING | C90: AYU | D90: S1 Informatika | E90: Software Engineering and Algoritm (SEAL) | F90: Lektor | G90: =VLOOKUP(B90,Sheet1!$C$2:$F$162,4,0) -> Computer Assisted Instruction
A91: 90 | B91: LAZUARDY SYAHRUL DARFIANSA | C91: LZD | D91: S1 PJJ Informatika | E91: Data Science and Intelligent Systems(DSIS) | F91: NJAD | G91: =VLOOKUP(B91,Sheet1!$C$2:$F$162,4,0) -> Text Mining & Processing
A92: 91 | B92: LIDYA NINGSIH | C92: LDS | D92: S1 Informatika | E92: Software Engineering and Algoritm (SEAL) | F92: Asisten Ahli | G92: =VLOOKUP(B92,Sheet1!$C$2:$F$162,4,0) -> Artificial Intelligence
A93: 92 | B93: MAHENDRA DWIFEBRI PURBOLAKSONO | C93: DWF | D93: S1 Rekayasa Perangkat Lunak | E93: Data Science and Intelligent Systems(DSIS) | F93: Lektor | G93: =VLOOKUP(B93,Sheet1!$C$2:$F$162,4,0) -> Text Mining & Processing
A94: 93 | B94: MAHMUD DWI SULISTIYO | C94: MDS | D94: S1 Informatika | E94: Data Science and Intelligent Systems(DSIS) | F94: Lektor | G94: =VLOOKUP(B94,Sheet1!$C$2:$F$162,4,0) -> Computer Vision
A95: 94 | B95: MAHMUD IMRONA | C95: MHD | D95: S1 Informatika | E95: Data Science and Intelligent Systems(DSIS) | F95: Lektor | G95: =VLOOKUP(B95,Sheet1!$C$2:$F$162,4,0) -> Data Modeling and Simulation
A96: 95 | B96: MAMAN ABDUROHMAN | C96: MMA | D96: S2 Informatika | E96: Communication and Information Technology Insfrastucture (CITI) | F96: Guru Besar | G96: =VLOOKUP(B96,Sheet1!$C$2:$F$162,4,0) -> Information Technology
A97: 96 | B97: MIFTAHUL ADNAN RASYID | C97: MIU | D97: S1 Rekayasa Perangkat Lunak | E97: Software Engineering and Algoritm (SEAL) | F97: NJAD | G97: =VLOOKUP(B97,Sheet1!$C$2:$F$162,4,0) -> Software Engineering
A98: 97 | B98: MIRA KANIA SABARIAH | C98: MKS | D98: S1 Rekayasa Perangkat Lunak | E98: Software Engineering and Algoritm (SEAL) | F98: Lektor | G98: =VLOOKUP(B98,Sheet1!$C$2:$F$162,4,0) -> Software Requirements
A99: 98 | B99: MOCH. ARIF BIJAKSANA | C99: MAB | D99: S1 Sains Data | E99: Data Science and Intelligent Systems(DSIS) | F99: Asisten Ahli | G99: Natural Language Processing
A100: 99 | B100: MONTERICO ADRIAN | C100: MTD | D100: S1 Teknologi Informasi | E100: Software Engineering and Algoritm (SEAL) | F100: Asisten Ahli | G100: =VLOOKUP(B100,Sheet1!$C$2:$F$162,4,0) -> Software Engineering
A101: 100 | B101: MUHAMAD IRSAN | C101: UIR | D101: S1 Teknologi Informasi | E101: Communication and Information Technology Insfrastucture (CITI) | F101: Lektor | G101: =VLOOKUP(B101,Sheet1!$C$2:$F$162,4,0) -> Information Technology
A102: 101 | B102: MUHAMMAD AL MAKKY | C102: MKY | D102: S1 Informatika | E102: Communication and Information Technology Insfrastucture (CITI) | F102: Asisten Ahli | G102: =VLOOKUP(B102,Sheet1!$C$2:$F$162,4,0) -> Information Technology
A103: 102 | B103: MUHAMMAD ARIEF NUGROHO | C103: MAN | D103: S1 Informatika | E103: Communication and Information Technology Insfrastucture (CITI) | F103: Asisten Ahli | G103: =VLOOKUP(B103,Sheet1!$C$2:$F$162,4,0) -> Information Technology
...

Sheet Sheet2
